2021-05-16 17:41:47,057 ERROR: Exception on / [GET] [in /home/whzheng/classroomLEDs/webApp/venv/lib/python3.7/site-packages/flask/app.py:1892]
Traceback (most recent call last):
  File "/home/whzheng/classroomLEDs/webApp/venv/lib/python3.7/site-packages/urllib3/connection.py", line 170, in _new_conn
    (self._dns_host, self.port), self.timeout, **extra_kw
  File "/home/whzheng/classroomLEDs/webApp/venv/lib/python3.7/site-packages/urllib3/util/connection.py", line 96, in create_connection
    raise err
  File "/home/whzheng/classroomLEDs/webApp/venv/lib/python3.7/site-packages/urllib3/util/connection.py", line 86, in create_connection
    sock.connect(sa)
ConnectionRefusedError: [Errno 111] Connection refused

During handling of the above exception, another exception occurred:

Traceback (most recent call last):
  File "/home/whzheng/classroomLEDs/webApp/venv/lib/python3.7/site-packages/urllib3/connectionpool.py", line 706, in urlopen
    chunked=chunked,
  File "/home/whzheng/classroomLEDs/webApp/venv/lib/python3.7/site-packages/urllib3/connectionpool.py", line 394, in _make_request
    conn.request(method, url, **httplib_request_kw)
  File "/home/whzheng/classroomLEDs/webApp/venv/lib/python3.7/site-packages/urllib3/connection.py", line 234, in request
    super(HTTPConnection, self).request(method, url, body=body, headers=headers)
  File "/usr/lib/python3.7/http/client.py", line 1244, in request
    self._send_request(method, url, body, headers, encode_chunked)
  File "/usr/lib/python3.7/http/client.py", line 1290, in _send_request
    self.endheaders(body, encode_chunked=encode_chunked)
  File "/usr/lib/python3.7/http/client.py", line 1239, in endheaders
    self._send_output(message_body, encode_chunked=encode_chunked)
  File "/usr/lib/python3.7/http/client.py", line 1026, in _send_output
    self.send(msg)
  File "/usr/lib/python3.7/http/client.py", line 966, in send
    self.connect()
  File "/home/whzheng/classroomLEDs/webApp/venv/lib/python3.7/site-packages/urllib3/connection.py", line 200, in connect
    conn = self._new_conn()
  File "/home/whzheng/classroomLEDs/webApp/venv/lib/python3.7/site-packages/urllib3/connection.py", line 182, in _new_conn
    self, "Failed to establish a new connection: %s" % e
urllib3.exceptions.NewConnectionError: <urllib3.connection.HTTPConnection object at 0x7fe9887db7f0>: Failed to establish a new connection: [Errno 111] Connection refused

During handling of the above exception, another exception occurred:

Traceback (most recent call last):
  File "/home/whzheng/classroomLEDs/webApp/venv/lib/python3.7/site-packages/requests/adapters.py", line 449, in send
    timeout=timeout
  File "/home/whzheng/classroomLEDs/webApp/venv/lib/python3.7/site-packages/urllib3/connectionpool.py", line 756, in urlopen
    method, url, error=e, _pool=self, _stacktrace=sys.exc_info()[2]
  File "/home/whzheng/classroomLEDs/webApp/venv/lib/python3.7/site-packages/urllib3/util/retry.py", line 574, in increment
    raise MaxRetryError(_pool, url, error or ResponseError(cause))
urllib3.exceptions.MaxRetryError: HTTPConnectionPool(host='localhost', port=3000): Max retries exceeded with url: /leds/1/scenes/60 (Caused by NewConnectionError('<urllib3.connection.HTTPConnection object at 0x7fe9887db7f0>: Failed to establish a new connection: [Errno 111] Connection refused'))

During handling of the above exception, another exception occurred:

Traceback (most recent call last):
  File "/home/whzheng/classroomLEDs/webApp/venv/lib/python3.7/site-packages/flask/app.py", line 2447, in wsgi_app
    response = self.full_dispatch_request()
  File "/home/whzheng/classroomLEDs/webApp/venv/lib/python3.7/site-packages/flask/app.py", line 1952, in full_dispatch_request
    rv = self.handle_user_exception(e)
  File "/home/whzheng/classroomLEDs/webApp/venv/lib/python3.7/site-packages/flask/app.py", line 1821, in handle_user_exception
    reraise(exc_type, exc_value, tb)
  File "/home/whzheng/classroomLEDs/webApp/venv/lib/python3.7/site-packages/flask/_compat.py", line 39, in reraise
    raise value
  File "/home/whzheng/classroomLEDs/webApp/venv/lib/python3.7/site-packages/flask/app.py", line 1950, in full_dispatch_request
    rv = self.dispatch_request()
  File "/home/whzheng/classroomLEDs/webApp/venv/lib/python3.7/site-packages/flask/app.py", line 1936, in dispatch_request
    return self.view_functions[rule.endpoint](**req.view_args)
  File "/home/whzheng/classroomLEDs/webApp/venv/lib/python3.7/site-packages/flask_login/utils.py", line 272, in decorated_view
    return func(*args, **kwargs)
  File "/home/whzheng/classroomLEDs/webApp/app/routes.py", line 50, in index
    r1 = requests.put(URL_put, json = data_put)
  File "/home/whzheng/classroomLEDs/webApp/venv/lib/python3.7/site-packages/requests/api.py", line 134, in put
    return request('put', url, data=data, **kwargs)
  File "/home/whzheng/classroomLEDs/webApp/venv/lib/python3.7/site-packages/requests/api.py", line 61, in request
    return session.request(method=method, url=url, **kwargs)
  File "/home/whzheng/classroomLEDs/webApp/venv/lib/python3.7/site-packages/requests/sessions.py", line 542, in request
    resp = self.send(prep, **send_kwargs)
  File "/home/whzheng/classroomLEDs/webApp/venv/lib/python3.7/site-packages/requests/sessions.py", line 655, in send
    r = adapter.send(request, **kwargs)
  File "/home/whzheng/classroomLEDs/webApp/venv/lib/python3.7/site-packages/requests/adapters.py", line 516, in send
    raise ConnectionError(e, request=request)
requests.exceptions.ConnectionError: HTTPConnectionPool(host='localhost', port=3000): Max retries exceeded with url: /leds/1/scenes/60 (Caused by NewConnectionError('<urllib3.connection.HTTPConnection object at 0x7fe9887db7f0>: Failed to establish a new connection: [Errno 111] Connection refused'))
2021-05-16 17:44:46,725 INFO: WebApp startup [in /home/whzheng/classroomLEDs/webApp/app/__init__.py:45]
2021-05-16 19:49:59,273 INFO: WebApp startup [in /home/whzheng/classroomLEDs/webApp/app/__init__.py:45]
2021-05-16 20:06:02,609 INFO: WebApp startup [in /home/whzheng/classroomLEDs/webApp/app/__init__.py:45]
2021-05-17 08:51:18,420 INFO: WebApp startup [in /home/whzheng/classroomLEDs/webApp/app/__init__.py:45]
